terminate called after throwing an instance of 'io::error::can_not_open_file'
  what():  Can not open file "/home/thib/Dropbox/Reaching Study/Gilwoo_Automated_v2/csv_only_manual_inspection/2016_12_14_study_4_Part10_1/2016_12_14_study_4_Part10_1_12431_12693_clean_phase1.csv" because "No such file or directory".
